Workbook

Sheet Sheet3

Sheet Sales_Data
A1: Order_ID | B1: Order_Date | C1: Customer_ID | D1: Customer_Name | E1: Gender | F1: Age | G1: City | H1: State | I1: Category | J1: Product | K1: Quantity | L1: Unit_Price | M1: Discount | N1: Sales | O1: Cost | P1: Profit | Q1: Payment_Mode | R1: Order_Status | S1: Rating
A2: ORD0001 | B2: 46072 | C2: CUST005 | D2: Nisha Verma | E2: Male | F2: 52 | G2: Ahmedabad | H2: Gujarat | I2: Electronics | J2: Bluetooth Speaker | K2: 3 | L2: 2499 | M2: 0.05 | N2: 7122.15 | O2: 4800 | P2: 2322.15 | Q2: Credit Card | R2: Delivered | S2: 5
A3: ORD0002 | B3: 46221 | C3: CUST095 | D3: Isha Mishra | E3: Female | F3: 29 | G3: Pune | H3: Maharashtra | I3: Beauty | J3: Shampoo | K3: 3 | L3: 599 | M3: 0.15 | N3: 1527.45 | O3: 960 | P3: 567.45 | Q3: Debit Card | R3: Delivered | S3: 4
A4: ORD0003 | B4: 45781 | C4: CUST070 | D4: Vikas Gupta | E4: Male | F4: 39 | G4: Kanpur | H4: Uttar Pradesh | I4: Clothing | J4: Hoodie | K4: 3 | L4: 1599 | M4: 0.05 | N4: 4557.15 | O4: 2850 | P4: 1707.15 | Q4: Credit Card | R4: Delivered | S4: 5
A5: ORD0004 | B5: 45941 | C5: CUST048 | D5: Nisha Kumar | E5: Female | F5: 26 | G5: Lucknow | H5: Uttar Pradesh | I5: Clothing | J5: T-Shirt | K5: 2 | L5: 799 | M5: 0.15 | N5: 1358.3 | O5: 900 | P5: 458.3 | Q5: Cash on Delivery | R5: Returned | S5: 5
A6: ORD0005 | B6: 45890 | C6: CUST073 | D6: Anjali Yadav | E6: Male | F6: 34 | G6: Mumbai | H6: Maharashtra | I6: Electronics | J6: USB Keyboard | K6: 2 | L6: 899 | M6: 0.1 | N6: 1618.2 | O6: 1100 | P6: 518.2 | Q6: Debit Card | R6: Delivered | S6: 1
A7: ORD0006 | B7: 45713 | C7: CUST137 | D7: Varun Sharma | E7: Female | F7: 25 | G7: Indore | H7: Madhya Pradesh | I7: Electronics | J7: Power Bank | K7: 3 | L7: 1299 | M7: 0 | N7: 3897 | O7: 2400 | P7: 1497 | Q7: Cash on Delivery | R7: Delivered | S7: 2
A8: ORD0007 | B8: 45949 | C8: CUST126 | D8: Sahil Patel | E8: Female | F8: 31 | G8: Pune | H8: Maharashtra | I8: Electronics | J8: USB Keyboard | K8: 1 | L8: 899 | M8: 0.2 | N8: 719.2 | O8: 550 | P8: 169.2 | Q8: Net Banking | R8: Delivered | S8: 3
A9: ORD0008 | B9: 45774 | C9: CUST048 | D9: Nisha Kumar | E9: Female | F9: 26 | G9: Lucknow | H9: Uttar Pradesh | I9: Electronics | J9: Smart Watch | K9: 3 | L9: 2999 | M9: 0.15 | N9: 7647.45 | O9: 5700 | P9: 1947.45 | Q9: UPI | R9: Delivered | S9: 1
A10: ORD0009 | B10: 45810 | C10: CUST148 | D10: Rahul Jain | E10: Female | F10: 53 | G10: Chennai | H10: Tamil Nadu | I10: Grocery | J10: Green Tea | K10: 1 | L10: 399 | M10: 0.05 | N10: 379.05 | O10: 220 | P10: 159.05 | Q10: Cash on Delivery | R10: Cancelled | S10: 1
A11: ORD0010 | B11: 45889 | C11: CUST064 | D11: Riya Verma | E11: Male | F11: 22 | G11: Bengaluru | H11: Karnataka | I11: Electronics | J11: USB Keyboard | K11: 4 | L11: 899 | M11: 0.2 | N11: 2876.8 | O11: 2200 | P11: 676.8 | Q11: Cash on Delivery | R11: Delivered | S11: 4
A12: ORD0011 | B12: 46240 | C12: CUST077 | D12: Simran Verma | E12: Female | F12: 20 | G12: Kanpur | H12: Uttar Pradesh | I12: Grocery | J12: Coffee | K12: 4 | L12: 499 | M12: 0.1 | N12: 1796.4 | O12: 1200 | P12: 596.4 | Q12: Cash on Delivery | R12: Delivered | S12: 1
A13: ORD0012 | B13: 45741 | C13: CUST054 | D13: Kavya Kumar | E13: Female | F13: 53 | G13: Kanpur | H13: Uttar Pradesh | I13: Grocery | J13: Green Tea | K13: 2 | L13: 399 | M13: 0.1 | N13: 718.2 | O13: 440 | P13: 278.2 | Q13: Credit Card | R13: Delivered | S13: 5
... A1001: ORD1000 | B1001: 45955 | C1001: CUST008 | D1001: Sneha Patel | E1001: Male | F1001: 42 | G1001: Indore | H1001: Madhya Pradesh | I1001: Beauty | J1001: Perfume | K1001: 1 | L1001: 1499 | M1001: 0.05 | N1001: 1424.05 | O1001: 850 | P1001: 574.05 | Q1001: Net Banking | R1001: Delivered | S1001: 5

Sheet Raw_Data
A1: Order_ID | B1: Order_Date | C1: Customer_ID | D1: Customer_Name | E1: Gender | F1: Age | G1: City | H1: State | I1: Category | J1: Product | K1: Quantity | L1: Unit_Price | M1: Discount | N1: Sales | O1: Cost | P1: Profit | Q1: Payment_Mode | R1: Order_Status | S1: Rating
A2: ORD0001 | B2: 46072 | C2: CUST005 | D2: Nisha Verma | E2: Male | F2: 52 | G2: Ahmedabad | H2: Gujarat | I2: Electronics | J2: Bluetooth Speaker | K2: 3 | L2: 2499 | M2: 0.05 | N2: 7122.15 | O2: 4800 | P2: 2322.15 | Q2: Credit Card | R2: Delivered | S2: 5
A3: ORD0002 | B3: 46221 | C3: CUST095 | D3: Isha Mishra | E3: Female | F3: 29 | G3: Pune | H3: Maharashtra | I3: Beauty | J3: Shampoo | K3: 3 | L3: 599 | M3: 0.15 | N3: 1527.45 | O3: 960 | P3: 567.45 | Q3: Debit Card | R3: Delivered | S3: 4
A4: ORD0003 | B4: 45781 | C4: CUST070 | D4: Vikas Gupta | E4: Male | F4: 39 | G4: Kanpur | H4: Uttar Pradesh | I4: Clothing | J4: Hoodie | K4: 3 | L4: 1599 | M4: 0.05 | N4: 4557.15 | O4: 2850 | P4: 1707.15 | Q4: Credit Card | R4: Delivered | S4: 5
A5: ORD0004 | B5: 45941 | C5: CUST048 | D5: Nisha Kumar | E5: Female | F5: 26 | G5: Lucknow | H5: Uttar Pradesh | I5: Clothing | J5: T-Shirt | K5: 2 | L5: 799 | M5: 0.15 | N5: 1358.3 | O5: 900 | P5: 458.3 | Q5: Cash on Delivery | R5: Returned | S5: 5
A6: ORD0005 | B6: 45890 | C6: CUST073 | D6: Anjali Yadav | E6: Male | F6: 34 | G6: Mumbai | H6: Maharashtra | I6: Electronics | J6: USB Keyboard | K6: 2 | L6: 899 | M6: 0.1 | N6: 1618.2 | O6: 1100 | P6: 518.2 | Q6: Debit Card | R6: Delivered | S6: 1
A7: ORD0006 | B7: 45713 | C7: CUST137 | D7: Varun Sharma | E7: Female | F7: 25 | G7: Indore | H7: Madhya Pradesh | I7: Electronics | J7: Power Bank | K7: 3 | L7: 1299 | M7: 0 | N7: 3897 | O7: 2400 | P7: 1497 | Q7: Cash on Delivery | R7: Delivered | S7: 2
A8: ORD0007 | B8: 45949 | C8: CUST126 | D8: Sahil Patel | E8: Female | F8: 31 | G8: Pune | H8: Maharashtra | I8: Electronics | J8: USB Keyboard | K8: 1 | L8: 899 | M8: 0.2 | N8: 719.2 | O8: 550 | P8: 169.2 | Q8: Net Banking | R8: Delivered | S8: 3
A9: ORD0008 | B9: 45774 | C9: CUST048 | D9: Nisha Kumar | E9: Female | F9: 26 | G9: Lucknow | H9: Uttar Pradesh | I9: Electronics | J9: Smart Watch | K9: 3 | L9: 2999 | M9: 0.15 | N9: 7647.45 | O9: 5700 | P9: 1947.45 | Q9: UPI | R9: Delivered | S9: 1
A10: ORD0009 | B10: 45810 | C10: CUST148 | D10: Rahul Jain | E10: Female | F10: 53 | G10: Chennai | H10: Tamil Nadu | I10: Grocery | J10: Green Tea | K10: 1 | L10: 399 | M10: 0.05 | N10: 379.05 | O10: 220 | P10: 159.05 | Q10: Cash on Delivery | R10: Cancelled | S10: 1
A11: ORD0010 | B11: 45889 | C11: CUST064 | D11: Riya Verma | E11: Male | F11: 22 | G11: Bengaluru | H11: Karnataka | I11: Electronics | J11: USB Keyboard | K11: 4 | L11: 899 | M11: 0.2 | N11: 2876.8 | O11: 2200 | P11: 676.8 | Q11: Cash on Delivery | R11: Delivered | S11: 4
A12: ORD0011 | B12: 46240 | C12: CUST077 | D12: Simran Verma | E12: Female | F12: 20 | G12: Kanpur | H12: Uttar Pradesh | I12: Grocery | J12: Coffee | K12: 4 | L12: 499 | M12: 0.1 | N12: 1796.4 | O12: 1200 | P12: 596.4 | Q12: Cash on Delivery | R12: Delivered | S12: 1
A13: ORD0012 | B13: 45741 | C13: CUST054 | D13: Kavya Kumar | E13: Female | F13: 53 | G13: Kanpur | H13: Uttar Pradesh | I13: Grocery | J13: Green Tea | K13: 2 | L13: 399 | M13: 0.1 | N13: 718.2 | O13: 440 | P13: 278.2 | Q13: Credit Card | R13: Delivered | S13: 5
... A1001: ORD1000 | B1001: 45955 | C1001: CUST008 | D1001: Sneha Patel | E1001: Male | F1001: 42 | G1001: Indore | H1001: Madhya Pradesh | I1001: Beauty | J1001: Perfume | K1001: 1 | L1001: 1499 | M1001: 0.05 | N1001: 1424.05 | O1001: 850 | P1001: 574.05 | Q1001: Net Banking | R1001: Delivered | S1001: 5

Sheet Read_Me
A1: E-Commerce Sales & Customer Analytics Project
A3: Dataset | B3: 1,000 realistic transaction records
A4: Customers | B4: 150 customer IDs with repeat purchases
A5: Period | B5: 2025-01-01 to 2026-09-01
A7: Next step | B7: Copy Raw_Data into your project workbook, then build PivotTables and the dashboard.

Sheet Analysis
A1: E-Commerce Sales Analysis
A3: Total Sales | B3: =SUM(SalesData[Sales]) -> 3393804.9
A4: Total Orders | B4: =COUNTA(SalesData[Order_ID]) -> 1000
A5: Total Profit | B5: =SUM(SalesData[Profit]) -> 1113525
A6: Total Customers | B6: =SUMPRODUCT((SalesData[Customer_ID]<>"")/COUNTIF(SalesData[Customer_ID],SalesData[Customer_ID]&"")) -> 150
A7: Average Order Value | B7: =B3/B4 -> 3393.8049
A8: Profit Margin | B8: =B5/B3 -> 0.32810517
A11: Monthly Sales Analysis | F11: State Analysis | K11: Top Products Analysis | P11: Customer Analytics
A12: Month | B12: Sales | C12: Profit | D12: Orders | F12: State | G12: Sales | H12: Profit | I12: Orders | K12: Product | L12: Sales | M12: Profit | N12: Orders | P12: Customer ID | Q12: Customer Name | R12: Total Sales | S12: Total Profit | T12: Orders
A13: Jan | B13: =SUMPRODUCT((MONTH(SalesData[Order_Date])=ROW()-12)*SalesData[Sales]) -> 331524.35 | C13: =SUMPRODUCT((TEXT(SalesData[Order_Date],"mmm")=A13)*SalesData[Profit]) -> 109384.35 | D13: =SUMPRODUCT(--(TEXT(SalesData[Order_Date],"mmm")=A13)) -> 97 | F13: Madhya Pradesh | G13: =SUMIF(SalesData[State],F13,SalesData[Sales]) -> 428300 | H13: =SUMIF(SalesData[State],F13,SalesData[Profit]) -> 139160 | I13: =COUNTIF(SalesData[State],F13) -> 116 | K13: Mixer Grinder | L13: =SUMIF(SalesData[Product],K13,SalesData[Sales]) -> 339752.9 | M13: =SUMIF(SalesData[Product],K13,SalesData[Profit]) -> 104352.9 | N13: =COUNTIF(SalesData[Product],K13) -> 43 | P13: ="CUST"&TEXT(ROW()-12,"000") -> CUST001 | Q13: =INDEX(SalesData[Customer_Name],MATCH(P13,SalesData[Customer_ID],0)) -> Arjun Verma | R13: =SUMIF(SalesData[Customer_ID],P13,SalesData[Sales]) -> 15740.3 | S13: =SUMIF(SalesData[Customer_ID],P13,SalesData[Profit]) -> 5090.3 | T13: =COUNTIF(SalesData[Customer_ID],P13) -> 3
A14: Feb | B14: =SUMPRODUCT((MONTH(SalesData[Order_Date])=ROW()-12)*SalesData[Sales]) -> 323925.95 | C14: =SUMPRODUCT((TEXT(SalesData[Order_Date],"mmm")=A14)*SalesData[Profit]) -> 109435.95 | D14: =SUMPRODUCT(--(TEXT(SalesData[Order_Date],"mmm")=A14)) -> 94 | F14: Delhi | G14: =SUMIF(SalesData[State],F14,SalesData[Sales]) -> 45191.9 | H14: =SUMIF(SalesData[State],F14,SalesData[Profit]) -> 14901.9 | I14: =COUNTIF(SalesData[State],F14) -> 14 | K14: Smart Watch | L14: =SUMIF(SalesData[Product],K14,SalesData[Sales]) -> 263012.3 | M14: =SUMIF(SalesData[Product],K14,SalesData[Profit]) -> 82512.3 | N14: =COUNTIF(SalesData[Product],K14) -> 38 | P14: ="CUST"&TEXT(ROW()-12,"000") -> CUST002 | Q14: =INDEX(SalesData[Customer_Name],MATCH(P14,SalesData[Customer_ID],0)) -> Riya Singh | R14: =SUMIF(SalesData[Customer_ID],P14,SalesData[Sales]) -> 22221.75 | S14: =SUMIF(SalesData[Customer_ID],P14,SalesData[Profit]) -> 7651.75 | T14: =COUNTIF(SalesData[Customer_ID],P14) -> 7
A15: Mar | B15: =SUMPRODUCT((MONTH(SalesData[Order_Date])=ROW()-12)*SalesData[Sales]) -> 343384.05 | C15: =SUMPRODUCT((TEXT(SalesData[Order_Date],"mmm")=A15)*SalesData[Profit]) -> 113364.05 | D15: =SUMPRODUCT(--(TEXT(SalesData[Order_Date],"mmm")=A15)) -> 97 | F15: Uttar Pradesh | G15: =SUMIF(SalesData[State],F15,SalesData[Sales]) -> 758386.5 | H15: =SUMIF(SalesData[State],F15,SalesData[Profit]) -> 251506.5 | I15: =COUNTIF(SalesData[State],F15) -> 209 | K15: Bluetooth Speaker | L15: =SUMIF(SalesData[Product],K15,SalesData[Sales]) -> 224410.2 | M15: =SUMIF(SalesData[Product],K15,SalesData[Profit]) -> 66010.2 | N15: =COUNTIF(SalesData[Product],K15) -> 36 | P15: ="CUST"&TEXT(ROW()-12,"000") -> CUST003 | Q15: =INDEX(SalesData[Customer_Name],MATCH(P15,SalesData[Customer_ID],0)) -> Rahul Singh | R15: =SUMIF(SalesData[Customer_ID],P15,SalesData[Sales]) -> 4591.35 | S15: =SUMIF(SalesData[Customer_ID],P15,SalesData[Profit]) -> 1921.35 | T15: =COUNTIF(SalesData[Customer_ID],P15) -> 3
A16: Apr | B16: =SUMPRODUCT((MONTH(SalesData[Order_Date])=ROW()-12)*SalesData[Sales]) -> 394023.15 | C16: =SUMPRODUCT((TEXT(SalesData[Order_Date],"mmm")=A16)*SalesData[Profit]) -> 131133.15 | D16: =SUMPRODUCT(--(TEXT(SalesData[Order_Date],"mmm")=A16)) -> 121 | F16: Maharashtra | G16: =SUMIF(SalesData[State],F16,SalesData[Sales]) -> 379622.6 | H16: =SUMIF(SalesData[State],F16,SalesData[Profit]) -> 127522.6 | I16: =COUNTIF(SalesData[State],F16) -> 117 | K16: Running Shoes | L16: =SUMIF(SalesData[Product],K16,SalesData[Sales]) -> 218627.1 | M16: =SUMIF(SalesData[Product],K16,SalesData[Profit]) -> 72827.1 | N16: =COUNTIF(SalesData[Product],K16) -> 33 | P16: ="CUST"&TEXT(ROW()-12,"000") -> CUST004 | Q16: =INDEX(SalesData[Customer_Name],MATCH(P16,SalesData[Customer_ID],0)) -> Isha Sharma | R16: =SUMIF(SalesData[Customer_ID],P16,SalesData[Sales]) -> 17698.9 | S16: =SUMIF(SalesData[Customer_ID],P16,SalesData[Profit]) -> 6398.9 | T16: =COUNTIF(SalesData[Customer_ID],P16) -> 5
A17: May | B17: =SUMPRODUCT((MONTH(SalesData[Order_Date])=ROW()-12)*SalesData[Sales]) -> 366339.05 | C17: =SUMPRODUCT((TEXT(SalesData[Order_Date],"mmm")=A17)*SalesData[Profit]) -> 119809.05 | D17: =SUMPRODUCT(--(TEXT(SalesData[Order_Date],"mmm")=A17)) -> 113 | F17: Rajasthan | G17: =SUMIF(SalesData[State],F17,SalesData[Sales]) -> 186677.2 | H17: =SUMIF(SalesData[State],F17,SalesData[Profit]) -> 59357.2 | I17: =COUNTIF(SalesData[State],F17) -> 54 | K17: Denim Jacket | L17: =SUMIF(SalesData[Product],K17,SalesData[Sales]) -> 202793.85 | M17: =SUMIF(SalesData[Product],K17,SalesData[Profit]) -> 64793.85 | N17: =COUNTIF(SalesData[Product],K17) -> 38 | P17: ="CUST"&TEXT(ROW()-12,"000") -> CUST005 | Q17: =INDEX(SalesData[Customer_Name],MATCH(P17,SalesData[Customer_ID],0)) -> Nisha Verma | R17: =SUMIF(SalesData[Customer_ID],P17,SalesData[Sales]) -> 40001.4 | S17: =SUMIF(SalesData[Customer_ID],P17,SalesData[Profit]) -> 13701.4 | T17: =COUNTIF(SalesData[Customer_ID],P17) -> 11
A18: Jun | B18: =SUMPRODUCT((MONTH(SalesData[Order_Date])=ROW()-12)*SalesData[Sales]) -> 285226.6 | C18: =SUMPRODUCT((TEXT(SalesData[Order_Date],"mmm")=A18)*SalesData[Profit]) -> 92036.6 | D18: =SUMPRODUCT(--(TEXT(SalesData[Order_Date],"mmm")=A18)) -> 93 | F18: Gujarat | G18: =SUMIF(SalesData[State],F18,SalesData[Sales]) -> 281047.1 | H18: =SUMIF(SalesData[State],F18,SalesData[Profit]) -> 92717.1 | I18: =COUNTIF(SalesData[State],F18) -> 83 | K18: Wireless Headphones | L18: =SUMIF(SalesData[Product],K18,SalesData[Sales]) -> 182708.6 | M18: =SUMIF(SalesData[Product],K18,SalesData[Profit]) -> 51408.6 | N18: =COUNTIF(SalesData[Product],K18) -> 39 | P18: ="CUST"&TEXT(ROW()-12,"000") -> CUST006 | Q18: =INDEX(SalesData[Customer_Name],MATCH(P18,SalesData[Customer_ID],0)) -> Anjali Mehta | R18: =SUMIF(SalesData[Customer_ID],P18,SalesData[Sales]) -> 29446.7 | S18: =SUMIF(SalesData[Customer_ID],P18,SalesData[Profit]) -> 7396.7 | T18: =COUNTIF(SalesData[Customer_ID],P18) -> 7
A19: Jul | B19: =SUMPRODUCT((MONTH(SalesData[Order_Date])=ROW()-12)*SalesData[Sales]) -> 343299.65 | C19: =SUMPRODUCT((TEXT(SalesData[Order_Date],"mmm")=A19)*SalesData[Profit]) -> 111969.65 | D19: =SUMPRODUCT(--(TEXT(SalesData[Order_Date],"mmm")=A19)) -> 93 | F19: West Bengal | G19: =SUMIF(SalesData[State],F19,SalesData[Sales]) -> 285311.2 | H19: =SUMIF(SalesData[State],F19,SalesData[Profit]) -> 91781.2 | I19: =COUNTIF(SalesData[State],F19) -> 84 | K19: Dinner Set | L19: =SUMIF(SalesData[Product],K19,SalesData[Sales]) -> 181409.25 | M19: =SUMIF(SalesData[Product],K19,SalesData[Profit]) -> 60209.25 | N19: =COUNTIF(SalesData[Product],K19) -> 40 | P19: ="CUST"&TEXT(ROW()-12,"000") -> CUST007 | Q19: =INDEX(SalesData[Customer_Name],MATCH(P19,SalesData[Customer_ID],0)) -> Vikas Patel | R19: =SUMIF(SalesData[Customer_ID],P19,SalesData[Sales]) -> 13884.15 | S19: =SUMIF(SalesData[Customer_ID],P19,SalesData[Profit]) -> 4004.15 | T19: =COUNTIF(SalesData[Customer_ID],P19) -> 5
A20: Aug | B20: =SUMPRODUCT((MONTH(SalesData[Order_Date])=ROW()-12)*SalesData[Sales]) -> 345958.55 | C20: =SUMPRODUCT((TEXT(SalesData[Order_Date],"mmm")=A20)*SalesData[Profit]) -> 107908.55 | D20: =SUMPRODUCT(--(TEXT(SalesData[Order_Date],"mmm")=A20)) -> 88 | F20: Karnataka | G20: =SUMIF(SalesData[State],F20,SalesData[Sales]) -> 176941.65 | H20: =SUMIF(SalesData[State],F20,SalesData[Profit]) -> 58581.65 | I20: =COUNTIF(SalesData[State],F20) -> 60 | K20: Hoodie | L20: =SUMIF(SalesData[Product],K20,SalesData[Sales]) -> 173731.35 | M20: =SUMIF(SalesData[Product],K20,SalesData[Profit]) -> 55931.35 | N20: =COUNTIF(SalesData[Product],K20) -> 45 | P20: ="CUST"&TEXT(ROW()-12,"000") -> CUST008 | Q20: =INDEX(SalesData[Customer_Name],MATCH(P20,SalesData[Customer_ID],0)) -> Sneha Patel | R20: =SUMIF(SalesData[Customer_ID],P20,SalesData[Sales]) -> 45878.65 | S20: =SUMIF(SalesData[Customer_ID],P20,SalesData[Profit]) -> 16098.65 | T20: =COUNTIF(SalesData[Customer_ID],P20) -> 9
A21: Sep | B21: =SUMPRODUCT((MONTH(SalesData[Order_Date])=ROW()-12)*SalesData[Sales]) -> 141223.9 | C21: =SUMPRODUCT((TEXT(SalesData[Order_Date],"mmm")=A21)*SalesData[Profit]) -> 46463.9 | D21: =SUMPRODUCT(--(TEXT(SalesData[Order_Date],"mmm")=A21)) -> 53 | F21: Tamil Nadu | G21: =SUMIF(SalesData[State],F21,SalesData[Sales]) -> 169512.25 | H21: =SUMIF(SalesData[State],F21,SalesData[Profit]) -> 54382.25 | I21: =COUNTIF(SalesData[State],F21) -> 55 | K21: Cricket Bat | L21: =SUMIF(SalesData[Product],K21,SalesData[Sales]) -> 171431.4 | M21: =SUMIF(SalesData[Product],K21,SalesData[Profit]) -> 54431.4 | N21: =COUNTIF(SalesData[Product],K21) -> 32 | P21: ="CUST"&TEXT(ROW()-12,"000") -> CUST009 | Q21: =INDEX(SalesData[Customer_Name],MATCH(P21,SalesData[Customer_ID],0)) -> Priya Yadav | R21: =SUMIF(SalesData[Customer_ID],P21,SalesData[Sales]) -> 45375.75 | S21: =SUMIF(SalesData[Customer_ID],P21,SalesData[Profit]) -> 15275.75 | T21: =COUNTIF(SalesData[Customer_ID],P21) -> 11
A22: Oct | B22: =SUMPRODUCT((MONTH(SalesData[Order_Date])=ROW()-12)*SalesData[Sales]) -> 159541.8 | C22: =SUMPRODUCT((TEXT(SalesData[Order_Date],"mmm")=A22)*SalesData[Profit]) -> 55351.8 | D22: =SUMPRODUCT(--(TEXT(SalesData[Order_Date],"mmm")=A22)) -> 52 | F22: Telangana | G22: =SUMIF(SalesData[State],F22,SalesData[Sales]) -> 345346.9 | H22: =SUMIF(SalesData[State],F22,SalesData[Profit]) -> 113486.9 | I22: =COUNTIF(SalesData[State],F22) -> 104 | K22: Electric Kettle | L22: =SUMIF(SalesData[Product],K22,SalesData[Sales]) -> 166838.7 | M22: =SUMIF(SalesData[Product],K22,SalesData[Profit]) -> 54338.7 | N22: =COUNTIF(SalesData[Product],K22) -> 51 | P22: ="CUST"&TEXT(ROW()-12,"000") -> CUST010 | Q22: =INDEX(SalesData[Customer_Name],MATCH(P22,SalesData[Customer_ID],0)) -> Amit Jain | R22: =SUMIF(SalesData[Customer_ID],P22,SalesData[Sales]) -> 16994.05 | S22: =SUMIF(SalesData[Customer_ID],P22,SalesData[Profit]) -> 5584.05 | T22: =COUNTIF(SalesData[Customer_ID],P22) -> 5
A23: Nov | B23: =SUMPRODUCT((MONTH(SalesData[Order_Date])=ROW()-12)*SalesData[Sales]) -> 225986.9 | C23: =SUMPRODUCT((TEXT(SalesData[Order_Date],"mmm")=A23)*SalesData[Profit]) -> 70206.9 | D23: =SUMPRODUCT(--(TEXT(SalesData[Order_Date],"mmm")=A23)) -> 61 | F23: Bihar | G23: =SUMIF(SalesData[State],F23,SalesData[Sales]) -> 263031.9 | H23: =SUMIF(SalesData[State],F23,SalesData[Profit]) -> 85871.9 | I23: =COUNTIF(SalesData[State],F23) -> 75 | P23: ="CUST"&TEXT(ROW()-12,"000") -> CUST011 | Q23: =INDEX(SalesData[Customer_Name],MATCH(P23,SalesData[Customer_ID],0)) -> Vikas Singh | R23: =SUMIF(SalesData[Customer_ID],P23,SalesData[Sales]) -> 12664.35 | S23: =SUMIF(SalesData[Customer_ID],P23,SalesData[Profit]) -> 3274.35 | T23: =COUNTIF(SalesData[Customer_ID],P23) -> 6
A24: Dec | B24: =SUMPRODUCT((MONTH(SalesData[Order_Date])=ROW()-12)*SalesData[Sales]) -> 133371 | C24: =SUMPRODUCT((TEXT(SalesData[Order_Date],"mmm")=A24)*SalesData[Profit]) -> 46461 | D24: =SUMPRODUCT(--(TEXT(SalesData[Order_Date],"mmm")=A24)) -> 38 | F24: Haryana | G24: =SUMIF(SalesData[State],F24,SalesData[Sales]) -> 0 | H24: =SUMIF(SalesData[State],F24,SalesData[Profit]) -> 0 | I24: =COUNTIF(SalesData[State],F24) -> 0 | P24: ="CUST"&TEXT(ROW()-12,"000") -> CUST012 | Q24: =INDEX(SalesData[Customer_Name],MATCH(P24,SalesData[Customer_ID],0)) -> Amit Verma | R24: =SUMIF(SalesData[Customer_ID],P24,SalesData[Sales]) -> 45278.65 | S24: =SUMIF(SalesData[Customer_ID],P24,SalesData[Profit]) -> 13928.65 | T24: =COUNTIF(SalesData[Customer_ID],P24) -> 7
F25: Punjab | G25: =SUMIF(SalesData[State],F25,SalesData[Sales]) -> 0 | H25: =SUMIF(SalesData[State],F25,SalesData[Profit]) -> 0 | I25: =COUNTIF(SalesData[State],F25) -> 0 | P25: ="CUST"&TEXT(ROW()-12,"000") -> CUST013 | Q25: =INDEX(SalesData[Customer_Name],MATCH(P25,SalesData[Customer_ID],0)) -> Arjun Yadav | R25: =SUMIF(SalesData[Customer_ID],P25,SalesData[Sales]) -> 27372.55 | S25: =SUMIF(SalesData[Customer_ID],P25,SalesData[Profit]) -> 9172.55 | T25: =COUNTIF(SalesData[Customer_ID],P25) -> 8
A26: Category Analysis | F26: Odisha | G26: =SUMIF(SalesData[State],F26,SalesData[Sales]) -> 0 | H26: =SUMIF(SalesData[State],F26,SalesData[Profit]) -> 0 | I26: =COUNTIF(SalesData[State],F26) -> 0 | P26: ="CUST"&TEXT(ROW()-12,"000") -> CUST014 | Q26: =INDEX(SalesData[Customer_Name],MATCH(P26,SalesData[Customer_ID],0)) -> Simran Patel | R26: =SUMIF(SalesData[Customer_ID],P26,SalesData[Sales]) -> 36052.55 | S26: =SUMIF(SalesData[Customer_ID],P26,SalesData[Profit]) -> 10902.55 | T26: =COUNTIF(SalesData[Customer_ID],P26) -> 11
A27: Category | B27: Sales | C27: Profit | D27: Orders | F27: Kerala | G27: =SUMIF(SalesData[State],F27,SalesData[Sales]) -> 0 | H27: =SUMIF(SalesData[State],F27,SalesData[Profit]) -> 0 | I27: =COUNTIF(SalesData[State],F27) -> 0 | P27: ="CUST"&TEXT(ROW()-12,"000") -> CUST015 | Q27: =INDEX(SalesData[Customer_Name],MATCH(P27,SalesData[Customer_ID],0)) -> Isha Kumar | R27: =SUMIF(SalesData[Customer_ID],P27,SalesData[Sales]) -> 26577.75 | S27: =SUMIF(SalesData[Customer_ID],P27,SalesData[Profit]) -> 9607.75 | T27: =COUNTIF(SalesData[Customer_ID],P27) -> 8
A28: Electronics | B28: =SUMIF(SalesData[Category],A28,SalesData[Sales]) -> 896964.9 | C28: =SUMIF(SalesData[Category],A28,SalesData[Profit]) -> 271514.9 | D28: =COUNTIF(SalesData[Category],A28) -> 204 | P28: ="CUST"&TEXT(ROW()-12,"000") -> CUST016 | Q28: =INDEX(SalesData[Customer_Name],MATCH(P28,SalesData[Customer_ID],0)) -> Sahil Mehta | R28: =SUMIF(SalesData[Customer_ID],P28,SalesData[Sales]) -> 12032.6 | S28: =SUMIF(SalesData[Customer_ID],P28,SalesData[Profit]) -> 4352.6 | T28: =COUNTIF(SalesData[Customer_ID],P28) -> 2
A29: Clothing | B29: =SUMIF(SalesData[Category],A29,SalesData[Sales]) -> 825759 | C29: =SUMIF(SalesData[Category],A29,SalesData[Profit]) -> 274759 | D29: =COUNTIF(SalesData[Category],A29) -> 196 | P29: ="CUST"&TEXT(ROW()-12,"000") -> CUST017 | Q29: =INDEX(SalesData[Customer_Name],MATCH(P29,SalesData[Customer_ID],0)) -> Priya Verma | R29: =SUMIF(SalesData[Customer_ID],P29,SalesData[Sales]) -> 26003.9 | S29: =SUMIF(SalesData[Customer_ID],P29,SalesData[Profit]) -> 9303.9 | T29: =COUNTIF(SalesData[Customer_ID],P29) -> 4
A30: Home & Kitchen | B30: =SUMIF(SalesData[Category],A30,SalesData[Sales]) -> 779459.3 | C30: =SUMIF(SalesData[Category],A30,SalesData[Profit]) -> 249159.3 | D30: =COUNTIF(SalesData[Category],A30) -> 170 | P30: ="CUST"&TEXT(ROW()-12,"000") -> CUST018 | Q30: =INDEX(SalesData[Customer_Name],MATCH(P30,SalesData[Customer_ID],0)) -> Aditya Gupta | R30: =SUMIF(SalesData[Customer_ID],P30,SalesData[Sales]) -> 13436.25 | S30: =SUMIF(SalesData[Customer_ID],P30,SalesData[Profit]) -> 3936.25 | T30: =COUNTIF(SalesData[Customer_ID],P30) -> 5
A31: Beauty | B31: =SUMIF(SalesData[Category],A31,SalesData[Sales]) -> 346986.55 | C31: =SUMIF(SalesData[Category],A31,SalesData[Profit]) -> 134926.55 | D31: =COUNTIF(SalesData[Category],A31) -> 172 | P31: ="CUST"&TEXT(ROW()-12,"000") -> CUST019 | Q31: =INDEX(SalesData[Customer_Name],MATCH(P31,SalesData[Customer_ID],0)) -> Karan Verma | R31: =SUMIF(SalesData[Customer_ID],P31,SalesData[Sales]) -> 23543.5 | S31: =SUMIF(SalesData[Customer_ID],P31,SalesData[Profit]) -> 7443.5 | T31: =COUNTIF(SalesData[Customer_ID],P31) -> 6
A32: Grocery | B32: =SUMIF(SalesData[Category],A32,SalesData[Sales]) -> 194478.35 | C32: =SUMIF(SalesData[Category],A32,SalesData[Profit]) -> 59658.35 | D32: =COUNTIF(SalesData[Category],A32) -> 137 | P32: ="CUST"&TEXT(ROW()-12,"000") -> CUST020 | Q32: =INDEX(SalesData[Customer_Name],MATCH(P32,SalesData[Customer_ID],0)) -> Sahil Kumar | R32: =SUMIF(SalesData[Customer_ID],P32,SalesData[Sales]) -> 31615.75 | S32: =SUMIF(SalesData[Customer_ID],P32,SalesData[Profit]) -> 8585.75 | T32: =COUNTIF(SalesData[Customer_ID],P32) -> 10
A33: Sports & Fitness | B33: =SUMIF(SalesData[Category],A33,SalesData[Sales]) -> 0 | C33: =SUMIF(SalesData[Category],A33,SalesData[Profit]) -> 0 | D33: =COUNTIF(SalesData[Category],A33) -> 0 | P33: ="CUST"&TEXT(ROW()-12,"000") -> CUST021 | Q33: =INDEX(SalesData[Customer_Name],MATCH(P33,SalesData[Customer_ID],0)) -> Riya Jain | R33: =SUMIF(SalesData[Customer_ID],P33,SalesData[Sales]) -> 41298.75 | S33: =SUMIF(SalesData[Customer_ID],P33,SalesData[Profit]) -> 13198.75 | T33: =COUNTIF(SalesData[Customer_ID],P33) -> 8
P34: ="CUST"&TEXT(ROW()-12,"000") -> CUST022 | Q34: =INDEX(SalesData[Customer_Name],MATCH(P34,SalesData[Customer_ID],0)) -> Aditya Patel | R34: =SUMIF(SalesData[Customer_ID],P34,SalesData[Sales]) -> 28284.4 | S34: =SUMIF(SalesData[Customer_ID],P34,SalesData[Profit]) -> 9484.4 | T34: =COUNTIF(SalesData[Customer_ID],P34) -> 6
P35: ="CUST"&TEXT(ROW()-12,"000") -> CUST023 | Q35: =INDEX(SalesData[Customer_Name],MATCH(P35,SalesData[Customer_ID],0)) -> Kavya Singh | R35: =SUMIF(SalesData[Customer_ID],P35,SalesData[Sales]) -> 45224.1 | S35: =SUMIF(SalesData[Customer_ID],P35,SalesData[Profit]) -> 15384.1 | T35: =COUNTIF(SalesData[Customer_ID],P35) -> 10
P36: ="CUST"&TEXT(ROW()-12,"000") -> CUST024 | Q36: =INDEX(SalesData[Customer_Name],MATCH(P36,SalesData[Customer_ID],0)) -> Rohan Kumar | R36: =SUMIF(SalesData[Customer_ID],P36,SalesData[Sales]) -> 12640 | S36: =SUMIF(SalesData[Customer_ID],P36,SalesData[Profit]) -> 4060 | T36: =COUNTIF(SalesData[Customer_ID],P36) -> 4
P37: ="CUST"&TEXT(ROW()-12,"000") -> CUST025 | Q37: =INDEX(SalesData[Customer_Name],MATCH(P37,SalesData[Customer_ID],0)) -> Aditya Mehta | R37: =SUMIF(SalesData[Customer_ID],P37,SalesData[Sales]) -> 24600.25 | S37: =SUMIF(SalesData[Customer_ID],P37,SalesData[Profit]) -> 7200.25 | T37: =COUNTIF(SalesData[Customer_ID],P37) -> 8
P38: ="CUST"&TEXT(ROW()-12,"000") -> CUST026 | Q38: =INDEX(SalesData[Customer_Name],MATCH(P38,SalesData[Customer_ID],0)) -> Arjun Jain | R38: =SUMIF(SalesData[Customer_ID],P38,SalesData[Sales]) -> 14998.35 | S38: =SUMIF(SalesData[Customer_ID],P38,SalesData[Profit]) -> 5348.35 | T38: =COUNTIF(SalesData[Customer_ID],P38) -> 6
P39: ="CUST"&TEXT(ROW()-12,"000") -> CUST027 | Q39: =INDEX(SalesData[Customer_Name],MATCH(P39,SalesData[Customer_ID],0)) -> Riya Gupta | R39: =SUMIF(SalesData[Customer_ID],P39,SalesData[Sales]) -> 50297.6 | S39: =SUMIF(SalesData[Customer_ID],P39,SalesData[Profit]) -> 16937.6 | T39: =COUNTIF(SalesData[Customer_ID],P39) -> 13
P40: ="CUST"&TEXT(ROW()-12,"000") -> CUST028 | Q40: =INDEX(SalesData[Customer_Name],MATCH(P40,SalesData[Customer_ID],0)) -> Pooja Mehta | R40: =SUMIF(SalesData[Customer_ID],P40,SalesData[Sales]) -> 33974.2 | S40: =SUMIF(SalesData[Customer_ID],P40,SalesData[Profit]) -> 10634.2 | T40: =COUNTIF(SalesData[Customer_ID],P40) -> 9
P41: ="CUST"&TEXT(ROW()-12,"000") -> CUST029 | Q41: =INDEX(SalesData[Customer_Name],MATCH(P41,SalesData[Customer_ID],0)) -> Arjun Jain | R41: =SUMIF(SalesData[Customer_ID],P41,SalesData[Sales]) -> 6414.5 | S41: =SUMIF(SalesData[Customer_ID],P41,SalesData[Profit]) -> 2084.5 | T41: =COUNTIF(SalesData[Customer_ID],P41) -> 5
P42: ="CUST"&TEXT(ROW()-12,"000") -> CUST030 | Q42: =INDEX(SalesData[Customer_Name],MATCH(P42,SalesData[Customer_ID],0)) -> Sneha Gupta | R42: =SUMIF(SalesData[Customer_ID],P42,SalesData[Sales]) -> 13176.15 | S42: =SUMIF(SalesData[Customer_ID],P42,SalesData[Profit]) -> 4176.15 | T42: =COUNTIF(SalesData[Customer_ID],P42) -> 4
P43: ="CUST"&TEXT(ROW()-12,"000") -> CUST031 | Q43: =INDEX(SalesData[Customer_Name],MATCH(P43,SalesData[Customer_ID],0)) -> Simran Kumar | R43: =SUMIF(SalesData[Customer_ID],P43,SalesData[Sales]) -> 34826.2 | S43: =SUMIF(SalesData[Customer_ID],P43,SalesData[Profit]) -> 11536.2 | T43: =COUNTIF(SalesData[Customer_ID],P43) -> 8
...

Sheet Dashboard
A1: E-COMMERCE SALES & CUSTOMER ANALYTICS DASHBOARD
A3: TOTAL SALES | C3: TOTAL ORDERS | E3: TOTAL PROFIT | G3: TOTAL CUSTOMERS
A4: =Analysis!B3 -> 3393804.9 | C4: =Analysis!B4 -> 1000 | E4: =Analysis!B5 -> 1113525 | G4: =Analysis!B6 -> 150
A6: AVERAGE ORDER VALUE | C6: PROFIT MARGIN
A7: =Analysis!B7 -> 3393.8049 | C7: =Analysis!B8 -> 0.32810517
